[2023-08-31T03:41:39.888+0000] {taskinstance.py:1159} INFO - Dependencies all met for dep_context=non-requeueable deps ti=<TaskInstance: website_crawler.crawl_task manual__2023-08-31T03:41:37.634092+00:00 [queued]>
[2023-08-31T03:41:39.902+0000] {taskinstance.py:1159} INFO - Dependencies all met for dep_context=requeueable deps ti=<TaskInstance: website_crawler.crawl_task manual__2023-08-31T03:41:37.634092+00:00 [queued]>
[2023-08-31T03:41:39.904+0000] {taskinstance.py:1361} INFO - Starting attempt 1 of 4
[2023-08-31T03:41:39.932+0000] {taskinstance.py:1382} INFO - Executing <Task(PythonOperator): crawl_task> on 2023-08-31 03:41:37.634092+00:00
[2023-08-31T03:41:39.947+0000] {standard_task_runner.py:57} INFO - Started process 75 to run task
[2023-08-31T03:41:39.957+0000] {standard_task_runner.py:84} INFO - Running: ['***', 'tasks', 'run', 'website_crawler', 'crawl_task', 'manual__2023-08-31T03:41:37.634092+00:00', '--job-id', '150', '--raw', '--subdir', 'DAGS_FOLDER/crawl_data_using_BeautifulSoup.py', '--cfg-path', '/tmp/tmp_w_0u9ww']
[2023-08-31T03:41:39.984+0000] {standard_task_runner.py:85} INFO - Job 150: Subtask crawl_task
[2023-08-31T03:41:40.223+0000] {task_command.py:415} INFO - Running <TaskInstance: website_crawler.crawl_task manual__2023-08-31T03:41:37.634092+00:00 [running]> on host b053bf73ca11
[2023-08-31T03:41:40.577+0000] {taskinstance.py:1660} INFO - Exporting env vars: AIRFLOW_CTX_DAG_OWNER='***' AIRFLOW_CTX_DAG_ID='website_crawler' AIRFLOW_CTX_TASK_ID='crawl_task' AIRFLOW_CTX_EXECUTION_DATE='2023-08-31T03:41:37.634092+00:00' AIRFLOW_CTX_TRY_NUMBER='1' AIRFLOW_CTX_DAG_RUN_ID='manual__2023-08-31T03:41:37.634092+00:00'
[2023-08-31T03:41:41.315+0000] {taskinstance.py:1943} ERROR - Task failed with exception
Traceback (most recent call last):
  File "/home/airflow/.local/lib/python3.8/site-packages/airflow/operators/python.py", line 192, in execute
    return_value = self.execute_callable()
  File "/home/airflow/.local/lib/python3.8/site-packages/airflow/operators/python.py", line 209, in execute_callable
    return self.python_callable(*self.op_args, **self.op_kwargs)
  File "/opt/airflow/dags/crawl_data_using_BeautifulSoup.py", line 50, in crawl_section_pages
    file_handler = logging.FileHandler('/Users/nguyenngocanh/Desktop/cohost AI/logs/test.txt')
  File "/usr/local/lib/python3.8/logging/__init__.py", line 1147, in __init__
    StreamHandler.__init__(self, self._open())
  File "/usr/local/lib/python3.8/logging/__init__.py", line 1176, in _open
    return open(self.baseFilename, self.mode, encoding=self.encoding)
FileNotFoundError: [Errno 2] No such file or directory: '/Users/nguyenngocanh/Desktop/cohost AI/logs/test.txt'
[2023-08-31T03:41:41.369+0000] {taskinstance.py:1400} INFO - Marking task as UP_FOR_RETRY. dag_id=website_crawler, task_id=crawl_task, execution_date=20230831T034137, start_date=20230831T034139, end_date=20230831T034141
[2023-08-31T03:41:41.391+0000] {standard_task_runner.py:104} ERROR - Failed to execute job 150 for task crawl_task ([Errno 2] No such file or directory: '/Users/nguyenngocanh/Desktop/cohost AI/logs/test.txt'; 75)
[2023-08-31T03:41:41.456+0000] {local_task_job_runner.py:228} INFO - Task exited with return code 1
[2023-08-31T03:41:41.499+0000] {taskinstance.py:2784} INFO - 0 downstream tasks scheduled from follow-on schedule check
