[2023-09-01T23:52:33.666+0000] {taskinstance.py:1159} INFO - Dependencies all met for dep_context=non-requeueable deps ti=<TaskInstance: website_crawler.crawl_task manual__2023-09-01T23:52:31.891620+00:00 [queued]>
[2023-09-01T23:52:33.694+0000] {taskinstance.py:1159} INFO - Dependencies all met for dep_context=requeueable deps ti=<TaskInstance: website_crawler.crawl_task manual__2023-09-01T23:52:31.891620+00:00 [queued]>
[2023-09-01T23:52:33.698+0000] {taskinstance.py:1361} INFO - Starting attempt 1 of 4
[2023-09-01T23:52:33.756+0000] {taskinstance.py:1382} INFO - Executing <Task(PythonOperator): crawl_task> on 2023-09-01 23:52:31.891620+00:00
[2023-09-01T23:52:33.786+0000] {standard_task_runner.py:57} INFO - Started process 64 to run task
[2023-09-01T23:52:33.831+0000] {standard_task_runner.py:84} INFO - Running: ['***', 'tasks', 'run', 'website_crawler', 'crawl_task', 'manual__2023-09-01T23:52:31.891620+00:00', '--job-id', '211', '--raw', '--subdir', 'DAGS_FOLDER/crawl_data_using_BeautifulSoup.py', '--cfg-path', '/tmp/tmpt_jq9qti']
[2023-09-01T23:52:33.855+0000] {standard_task_runner.py:85} INFO - Job 211: Subtask crawl_task
[2023-09-01T23:52:34.090+0000] {task_command.py:415} INFO - Running <TaskInstance: website_crawler.crawl_task manual__2023-09-01T23:52:31.891620+00:00 [running]> on host 200bc7f91af2
[2023-09-01T23:52:34.384+0000] {taskinstance.py:1660} INFO - Exporting env vars: AIRFLOW_CTX_DAG_OWNER='***' AIRFLOW_CTX_DAG_ID='website_crawler' AIRFLOW_CTX_TASK_ID='crawl_task' AIRFLOW_CTX_EXECUTION_DATE='2023-09-01T23:52:31.891620+00:00' AIRFLOW_CTX_TRY_NUMBER='1' AIRFLOW_CTX_DAG_RUN_ID='manual__2023-09-01T23:52:31.891620+00:00'
[2023-09-01T23:52:35.617+0000] {taskinstance.py:1943} ERROR - Task failed with exception
Traceback (most recent call last):
  File "/home/airflow/.local/lib/python3.8/site-packages/airflow/operators/python.py", line 192, in execute
    return_value = self.execute_callable()
  File "/home/airflow/.local/lib/python3.8/site-packages/airflow/operators/python.py", line 209, in execute_callable
    return self.python_callable(*self.op_args, **self.op_kwargs)
  File "/opt/airflow/dags/crawl_data_using_BeautifulSoup.py", line 48, in crawl_section_pages
    log_file = open(log_file_path, 'w')
FileNotFoundError: [Errno 2] No such file or directory: '/usr/local/airflow/dags/test.txt'
[2023-09-01T23:52:35.850+0000] {taskinstance.py:1400} INFO - Marking task as UP_FOR_RETRY. dag_id=website_crawler, task_id=crawl_task, execution_date=20230901T235231, start_date=20230901T235233, end_date=20230901T235235
[2023-09-01T23:52:35.930+0000] {standard_task_runner.py:104} ERROR - Failed to execute job 211 for task crawl_task ([Errno 2] No such file or directory: '/usr/local/airflow/dags/test.txt'; 64)
[2023-09-01T23:52:36.079+0000] {local_task_job_runner.py:228} INFO - Task exited with return code 1
[2023-09-01T23:52:36.148+0000] {taskinstance.py:2784} INFO - 0 downstream tasks scheduled from follow-on schedule check
