[2023-08-29T04:52:25.042+0000] {taskinstance.py:1159} INFO - Dependencies all met for dep_context=non-requeueable deps ti=<TaskInstance: website_crawler.crawl_task manual__2023-08-29T04:52:22.391545+00:00 [queued]>
[2023-08-29T04:52:25.246+0000] {taskinstance.py:1159} INFO - Dependencies all met for dep_context=requeueable deps ti=<TaskInstance: website_crawler.crawl_task manual__2023-08-29T04:52:22.391545+00:00 [queued]>
[2023-08-29T04:52:25.254+0000] {taskinstance.py:1361} INFO - Starting attempt 1 of 4
[2023-08-29T04:52:25.360+0000] {taskinstance.py:1382} INFO - Executing <Task(PythonOperator): crawl_task> on 2023-08-29 04:52:22.391545+00:00
[2023-08-29T04:52:25.406+0000] {standard_task_runner.py:57} INFO - Started process 55 to run task
[2023-08-29T04:52:25.437+0000] {standard_task_runner.py:84} INFO - Running: ['***', 'tasks', 'run', 'website_crawler', 'crawl_task', 'manual__2023-08-29T04:52:22.391545+00:00', '--job-id', '110', '--raw', '--subdir', 'DAGS_FOLDER/crawl_data_using_BeautifulSoup.py', '--cfg-path', '/tmp/tmpi7dex7nq']
[2023-08-29T04:52:25.481+0000] {standard_task_runner.py:85} INFO - Job 110: Subtask crawl_task
[2023-08-29T04:52:25.886+0000] {task_command.py:415} INFO - Running <TaskInstance: website_crawler.crawl_task manual__2023-08-29T04:52:22.391545+00:00 [running]> on host f38233847898
[2023-08-29T04:52:26.396+0000] {taskinstance.py:1660} INFO - Exporting env vars: AIRFLOW_CTX_DAG_OWNER='***' AIRFLOW_CTX_DAG_ID='website_crawler' AIRFLOW_CTX_TASK_ID='crawl_task' AIRFLOW_CTX_EXECUTION_DATE='2023-08-29T04:52:22.391545+00:00' AIRFLOW_CTX_TRY_NUMBER='1' AIRFLOW_CTX_DAG_RUN_ID='manual__2023-08-29T04:52:22.391545+00:00'
[2023-08-29T04:52:26.899+0000] {taskinstance.py:1943} ERROR - Task failed with exception
Traceback (most recent call last):
  File "/home/airflow/.local/lib/python3.8/site-packages/airflow/operators/python.py", line 192, in execute
    return_value = self.execute_callable()
  File "/home/airflow/.local/lib/python3.8/site-packages/airflow/operators/python.py", line 209, in execute_callable
    return self.python_callable(*self.op_args, **self.op_kwargs)
  File "/opt/airflow/dags/crawl_data_using_BeautifulSoup.py", line 40, in crawl_section_pages
    ti.log(ultag)
TypeError: 'Logger' object is not callable
[2023-08-29T04:52:26.933+0000] {taskinstance.py:1400} INFO - Marking task as UP_FOR_RETRY. dag_id=website_crawler, task_id=crawl_task, execution_date=20230829T045222, start_date=20230829T045225, end_date=20230829T045226
[2023-08-29T04:52:26.961+0000] {standard_task_runner.py:104} ERROR - Failed to execute job 110 for task crawl_task ('Logger' object is not callable; 55)
[2023-08-29T04:52:27.024+0000] {local_task_job_runner.py:228} INFO - Task exited with return code 1
[2023-08-29T04:52:27.074+0000] {taskinstance.py:2784} INFO - 0 downstream tasks scheduled from follow-on schedule check
