[2023-08-29T04:47:36.114+0000] {taskinstance.py:1159} INFO - Dependencies all met for dep_context=non-requeueable deps ti=<TaskInstance: website_crawler.crawl_task manual__2023-08-29T04:47:33.547066+00:00 [queued]>
[2023-08-29T04:47:36.125+0000] {taskinstance.py:1159} INFO - Dependencies all met for dep_context=requeueable deps ti=<TaskInstance: website_crawler.crawl_task manual__2023-08-29T04:47:33.547066+00:00 [queued]>
[2023-08-29T04:47:36.127+0000] {taskinstance.py:1361} INFO - Starting attempt 1 of 4
[2023-08-29T04:47:36.140+0000] {taskinstance.py:1382} INFO - Executing <Task(PythonOperator): crawl_task> on 2023-08-29 04:47:33.547066+00:00
[2023-08-29T04:47:36.147+0000] {standard_task_runner.py:57} INFO - Started process 68 to run task
[2023-08-29T04:47:36.153+0000] {standard_task_runner.py:84} INFO - Running: ['***', 'tasks', 'run', 'website_crawler', 'crawl_task', 'manual__2023-08-29T04:47:33.547066+00:00', '--job-id', '107', '--raw', '--subdir', 'DAGS_FOLDER/crawl_data_using_BeautifulSoup.py', '--cfg-path', '/tmp/tmp59tgu67j']
[2023-08-29T04:47:36.159+0000] {standard_task_runner.py:85} INFO - Job 107: Subtask crawl_task
[2023-08-29T04:47:36.270+0000] {task_command.py:415} INFO - Running <TaskInstance: website_crawler.crawl_task manual__2023-08-29T04:47:33.547066+00:00 [running]> on host f38233847898
[2023-08-29T04:47:36.451+0000] {taskinstance.py:1660} INFO - Exporting env vars: AIRFLOW_CTX_DAG_OWNER='***' AIRFLOW_CTX_DAG_ID='website_crawler' AIRFLOW_CTX_TASK_ID='crawl_task' AIRFLOW_CTX_EXECUTION_DATE='2023-08-29T04:47:33.547066+00:00' AIRFLOW_CTX_TRY_NUMBER='1' AIRFLOW_CTX_DAG_RUN_ID='manual__2023-08-29T04:47:33.547066+00:00'
[2023-08-29T04:47:37.094+0000] {taskinstance.py:1943} ERROR - Task failed with exception
Traceback (most recent call last):
  File "/home/airflow/.local/lib/python3.8/site-packages/airflow/operators/python.py", line 192, in execute
    return_value = self.execute_callable()
  File "/home/airflow/.local/lib/python3.8/site-packages/airflow/operators/python.py", line 209, in execute_callable
    return self.python_callable(*self.op_args, **self.op_kwargs)
  File "/opt/airflow/dags/crawl_data_using_BeautifulSoup.py", line 40, in crawl_section_pages
    len = len(ultag.find_all('li'))
UnboundLocalError: local variable 'len' referenced before assignment
[2023-08-29T04:47:37.121+0000] {taskinstance.py:1400} INFO - Marking task as UP_FOR_RETRY. dag_id=website_crawler, task_id=crawl_task, execution_date=20230829T044733, start_date=20230829T044736, end_date=20230829T044737
[2023-08-29T04:47:37.141+0000] {standard_task_runner.py:104} ERROR - Failed to execute job 107 for task crawl_task (local variable 'len' referenced before assignment; 68)
[2023-08-29T04:47:37.199+0000] {local_task_job_runner.py:228} INFO - Task exited with return code 1
[2023-08-29T04:47:37.225+0000] {taskinstance.py:2784} INFO - 0 downstream tasks scheduled from follow-on schedule check
