[2023-09-10T15:57:06.029+0000] {taskinstance.py:1159} INFO - Dependencies all met for dep_context=non-requeueable deps ti=<TaskInstance: website_crawler.crawl_task manual__2023-09-10T15:57:01.927148+00:00 [queued]>
[2023-09-10T15:57:06.090+0000] {taskinstance.py:1159} INFO - Dependencies all met for dep_context=requeueable deps ti=<TaskInstance: website_crawler.crawl_task manual__2023-09-10T15:57:01.927148+00:00 [queued]>
[2023-09-10T15:57:06.102+0000] {taskinstance.py:1361} INFO - Starting attempt 1 of 4
[2023-09-10T15:57:06.168+0000] {taskinstance.py:1382} INFO - Executing <Task(PythonOperator): crawl_task> on 2023-09-10 15:57:01.927148+00:00
[2023-09-10T15:57:06.218+0000] {standard_task_runner.py:57} INFO - Started process 77 to run task
[2023-09-10T15:57:06.274+0000] {standard_task_runner.py:84} INFO - Running: ['***', 'tasks', 'run', 'website_crawler', 'crawl_task', 'manual__2023-09-10T15:57:01.927148+00:00', '--job-id', '478', '--raw', '--subdir', 'DAGS_FOLDER/crawl_data_log_into_postgres.py', '--cfg-path', '/tmp/tmpegtew7cq']
[2023-09-10T15:57:06.307+0000] {standard_task_runner.py:85} INFO - Job 478: Subtask crawl_task
[2023-09-10T15:57:06.748+0000] {task_command.py:415} INFO - Running <TaskInstance: website_crawler.crawl_task manual__2023-09-10T15:57:01.927148+00:00 [running]> on host 30cb2bd58730
[2023-09-10T15:57:07.319+0000] {taskinstance.py:1660} INFO - Exporting env vars: AIRFLOW_CTX_DAG_OWNER='***' AIRFLOW_CTX_DAG_ID='website_crawler' AIRFLOW_CTX_TASK_ID='crawl_task' AIRFLOW_CTX_EXECUTION_DATE='2023-09-10T15:57:01.927148+00:00' AIRFLOW_CTX_TRY_NUMBER='1' AIRFLOW_CTX_DAG_RUN_ID='manual__2023-09-10T15:57:01.927148+00:00'
[2023-09-10T15:57:09.178+0000] {taskinstance.py:1943} ERROR - Task failed with exception
Traceback (most recent call last):
  File "/home/airflow/.local/lib/python3.8/site-packages/airflow/operators/python.py", line 192, in execute
    return_value = self.execute_callable()
  File "/home/airflow/.local/lib/python3.8/site-packages/airflow/operators/python.py", line 209, in execute_callable
    return self.python_callable(*self.op_args, **self.op_kwargs)
  File "/opt/airflow/dags/crawl_data_log_into_postgres.py", line 77, in crawl_section_pages
    pg_hook = PostgresHook(postgres_conn_id='postgres_local')
NameError: name 'PostgresHook' is not defined
[2023-09-10T15:57:09.575+0000] {taskinstance.py:1400} INFO - Marking task as UP_FOR_RETRY. dag_id=website_crawler, task_id=crawl_task, execution_date=20230910T155701, start_date=20230910T155706, end_date=20230910T155709
[2023-09-10T15:57:09.815+0000] {standard_task_runner.py:104} ERROR - Failed to execute job 478 for task crawl_task (name 'PostgresHook' is not defined; 77)
[2023-09-10T15:57:10.056+0000] {local_task_job_runner.py:228} INFO - Task exited with return code 1
[2023-09-10T15:57:10.426+0000] {taskinstance.py:2784} INFO - 0 downstream tasks scheduled from follow-on schedule check
