[2023-09-10T16:06:21.314+0000] {taskinstance.py:1159} INFO - Dependencies all met for dep_context=non-requeueable deps ti=<TaskInstance: website_crawler.crawl_task manual__2023-09-10T16:06:08.168802+00:00 [queued]>
[2023-09-10T16:06:21.449+0000] {taskinstance.py:1159} INFO - Dependencies all met for dep_context=requeueable deps ti=<TaskInstance: website_crawler.crawl_task manual__2023-09-10T16:06:08.168802+00:00 [queued]>
[2023-09-10T16:06:21.459+0000] {taskinstance.py:1361} INFO - Starting attempt 1 of 4
[2023-09-10T16:06:21.708+0000] {taskinstance.py:1382} INFO - Executing <Task(PythonOperator): crawl_task> on 2023-09-10 16:06:08.168802+00:00
[2023-09-10T16:06:21.746+0000] {standard_task_runner.py:57} INFO - Started process 65 to run task
[2023-09-10T16:06:21.778+0000] {standard_task_runner.py:84} INFO - Running: ['***', 'tasks', 'run', 'website_crawler', 'crawl_task', 'manual__2023-09-10T16:06:08.168802+00:00', '--job-id', '482', '--raw', '--subdir', 'DAGS_FOLDER/crawl_data_log_into_postgres.py', '--cfg-path', '/tmp/tmpolt7whcy']
[2023-09-10T16:06:21.809+0000] {standard_task_runner.py:85} INFO - Job 482: Subtask crawl_task
[2023-09-10T16:06:22.224+0000] {task_command.py:415} INFO - Running <TaskInstance: website_crawler.crawl_task manual__2023-09-10T16:06:08.168802+00:00 [running]> on host 30cb2bd58730
[2023-09-10T16:06:22.910+0000] {taskinstance.py:1660} INFO - Exporting env vars: AIRFLOW_CTX_DAG_OWNER='***' AIRFLOW_CTX_DAG_ID='website_crawler' AIRFLOW_CTX_TASK_ID='crawl_task' AIRFLOW_CTX_EXECUTION_DATE='2023-09-10T16:06:08.168802+00:00' AIRFLOW_CTX_TRY_NUMBER='1' AIRFLOW_CTX_DAG_RUN_ID='manual__2023-09-10T16:06:08.168802+00:00'
[2023-09-10T16:06:25.323+0000] {taskinstance.py:1943} ERROR - Task failed with exception
Traceback (most recent call last):
  File "/home/airflow/.local/lib/python3.8/site-packages/airflow/operators/python.py", line 192, in execute
    return_value = self.execute_callable()
  File "/home/airflow/.local/lib/python3.8/site-packages/airflow/operators/python.py", line 209, in execute_callable
    return self.python_callable(*self.op_args, **self.op_kwargs)
  File "/opt/airflow/dags/crawl_data_log_into_postgres.py", line 80, in crawl_section_pages
    logging("test -----------")
TypeError: 'module' object is not callable
[2023-09-10T16:06:25.532+0000] {taskinstance.py:1400} INFO - Marking task as UP_FOR_RETRY. dag_id=website_crawler, task_id=crawl_task, execution_date=20230910T160608, start_date=20230910T160621, end_date=20230910T160625
[2023-09-10T16:06:25.802+0000] {standard_task_runner.py:104} ERROR - Failed to execute job 482 for task crawl_task ('module' object is not callable; 65)
[2023-09-10T16:06:26.215+0000] {local_task_job_runner.py:228} INFO - Task exited with return code 1
[2023-09-10T16:06:26.525+0000] {taskinstance.py:2784} INFO - 0 downstream tasks scheduled from follow-on schedule check
