[2023-09-02T00:29:22.009+0000] {taskinstance.py:1159} INFO - Dependencies all met for dep_context=non-requeueable deps ti=<TaskInstance: website_crawler.crawl_task manual__2023-09-02T00:29:18.392890+00:00 [queued]>
[2023-09-02T00:29:22.062+0000] {taskinstance.py:1159} INFO - Dependencies all met for dep_context=requeueable deps ti=<TaskInstance: website_crawler.crawl_task manual__2023-09-02T00:29:18.392890+00:00 [queued]>
[2023-09-02T00:29:22.066+0000] {taskinstance.py:1361} INFO - Starting attempt 1 of 4
[2023-09-02T00:29:22.178+0000] {taskinstance.py:1382} INFO - Executing <Task(PythonOperator): crawl_task> on 2023-09-02 00:29:18.392890+00:00
[2023-09-02T00:29:22.243+0000] {standard_task_runner.py:57} INFO - Started process 56 to run task
[2023-09-02T00:29:22.273+0000] {standard_task_runner.py:84} INFO - Running: ['***', 'tasks', 'run', 'website_crawler', 'crawl_task', 'manual__2023-09-02T00:29:18.392890+00:00', '--job-id', '230', '--raw', '--subdir', 'DAGS_FOLDER/crawl_data_using_BeautifulSoup.py', '--cfg-path', '/tmp/tmptvph3kwe']
[2023-09-02T00:29:22.297+0000] {standard_task_runner.py:85} INFO - Job 230: Subtask crawl_task
[2023-09-02T00:29:22.616+0000] {task_command.py:415} INFO - Running <TaskInstance: website_crawler.crawl_task manual__2023-09-02T00:29:18.392890+00:00 [running]> on host 200bc7f91af2
[2023-09-02T00:29:23.060+0000] {taskinstance.py:1660} INFO - Exporting env vars: AIRFLOW_CTX_DAG_OWNER='***' AIRFLOW_CTX_DAG_ID='website_crawler' AIRFLOW_CTX_TASK_ID='crawl_task' AIRFLOW_CTX_EXECUTION_DATE='2023-09-02T00:29:18.392890+00:00' AIRFLOW_CTX_TRY_NUMBER='1' AIRFLOW_CTX_DAG_RUN_ID='manual__2023-09-02T00:29:18.392890+00:00'
[2023-09-02T00:29:24.095+0000] {crawl_data_using_BeautifulSoup.py:52} INFO - /opt/***/test.txt
[2023-09-02T00:29:56.674+0000] {taskinstance.py:1943} ERROR - Task failed with exception
Traceback (most recent call last):
  File "/home/airflow/.local/lib/python3.8/site-packages/urllib3/connectionpool.py", line 714, in urlopen
    httplib_response = self._make_request(
  File "/home/airflow/.local/lib/python3.8/site-packages/urllib3/connectionpool.py", line 466, in _make_request
    six.raise_from(e, None)
  File "<string>", line 3, in raise_from
  File "/home/airflow/.local/lib/python3.8/site-packages/urllib3/connectionpool.py", line 461, in _make_request
    httplib_response = conn.getresponse()
  File "/usr/local/lib/python3.8/http/client.py", line 1348, in getresponse
    response.begin()
  File "/usr/local/lib/python3.8/http/client.py", line 316, in begin
    version, status, reason = self._read_status()
  File "/usr/local/lib/python3.8/http/client.py", line 285, in _read_status
    raise RemoteDisconnected("Remote end closed connection without"
http.client.RemoteDisconnected: Remote end closed connection without response

During handling of the above exception, another exception occurred:

Traceback (most recent call last):
  File "/home/airflow/.local/lib/python3.8/site-packages/requests/adapters.py", line 486, in send
    resp = conn.urlopen(
  File "/home/airflow/.local/lib/python3.8/site-packages/urllib3/connectionpool.py", line 798, in urlopen
    retries = retries.increment(
  File "/home/airflow/.local/lib/python3.8/site-packages/urllib3/util/retry.py", line 550, in increment
    raise six.reraise(type(error), error, _stacktrace)
  File "/home/airflow/.local/lib/python3.8/site-packages/urllib3/packages/six.py", line 769, in reraise
    raise value.with_traceback(tb)
  File "/home/airflow/.local/lib/python3.8/site-packages/urllib3/connectionpool.py", line 714, in urlopen
    httplib_response = self._make_request(
  File "/home/airflow/.local/lib/python3.8/site-packages/urllib3/connectionpool.py", line 466, in _make_request
    six.raise_from(e, None)
  File "<string>", line 3, in raise_from
  File "/home/airflow/.local/lib/python3.8/site-packages/urllib3/connectionpool.py", line 461, in _make_request
    httplib_response = conn.getresponse()
  File "/usr/local/lib/python3.8/http/client.py", line 1348, in getresponse
    response.begin()
  File "/usr/local/lib/python3.8/http/client.py", line 316, in begin
    version, status, reason = self._read_status()
  File "/usr/local/lib/python3.8/http/client.py", line 285, in _read_status
    raise RemoteDisconnected("Remote end closed connection without"
urllib3.exceptions.ProtocolError: ('Connection aborted.', RemoteDisconnected('Remote end closed connection without response'))

During handling of the above exception, another exception occurred:

Traceback (most recent call last):
  File "/home/airflow/.local/lib/python3.8/site-packages/airflow/operators/python.py", line 192, in execute
    return_value = self.execute_callable()
  File "/home/airflow/.local/lib/python3.8/site-packages/airflow/operators/python.py", line 209, in execute_callable
    return self.python_callable(*self.op_args, **self.op_kwargs)
  File "/opt/airflow/dags/crawl_data_using_BeautifulSoup.py", line 60, in crawl_section_pages
    new_list = crawl_page(next_page_url, section_css_selector)
  File "/opt/airflow/dags/crawl_data_using_BeautifulSoup.py", line 20, in crawl_page
    response = requests.get(url)
  File "/home/airflow/.local/lib/python3.8/site-packages/requests/api.py", line 73, in get
    return request("get", url, params=params, **kwargs)
  File "/home/airflow/.local/lib/python3.8/site-packages/requests/api.py", line 59, in request
    return session.request(method=method, url=url, **kwargs)
  File "/home/airflow/.local/lib/python3.8/site-packages/requests/sessions.py", line 589, in request
    resp = self.send(prep, **send_kwargs)
  File "/home/airflow/.local/lib/python3.8/site-packages/requests/sessions.py", line 703, in send
    r = adapter.send(request, **kwargs)
  File "/home/airflow/.local/lib/python3.8/site-packages/requests/adapters.py", line 501, in send
    raise ConnectionError(err, request=request)
requests.exceptions.ConnectionError: ('Connection aborted.', RemoteDisconnected('Remote end closed connection without response'))
[2023-09-02T00:29:56.737+0000] {taskinstance.py:1400} INFO - Marking task as UP_FOR_RETRY. dag_id=website_crawler, task_id=crawl_task, execution_date=20230902T002918, start_date=20230902T002922, end_date=20230902T002956
[2023-09-02T00:29:56.764+0000] {standard_task_runner.py:104} ERROR - Failed to execute job 230 for task crawl_task (('Connection aborted.', RemoteDisconnected('Remote end closed connection without response')); 56)
[2023-09-02T00:29:56.929+0000] {local_task_job_runner.py:228} INFO - Task exited with return code 1
[2023-09-02T00:29:56.975+0000] {taskinstance.py:2784} INFO - 0 downstream tasks scheduled from follow-on schedule check
